Workbook

Sheet Bearing Life Calculator
B3: Bearing Life Calculator
B5: Parameters | C5: Value | D5: Unit
B6: Type of Bearing | C6: Deep Groove Ball Bearing
B7: Number of rows i | C7: 1
B8: Ball Diameter Dw | C8: 5 | D8: mm
B9: Factor depending upon size f | C9: =IF(C6="Spherical Roller Bearing",11.4,12.3) -> 12.3
B10: Dynamic Load Rating C0 | C10: =C9*C7*C8*C8 -> 307.5 | D10: N
B11: Radial Load Fr | C11: 10000 | D11: N
B12: Axial Load Fa | C12: 30000 | D12: N
B13: Radial Factor X | C13: ='X and Y factor Table'!B15 -> 0.56
B14: Axial Factor Y | C14: ='X and Y factor Table'!B16 -> 1
B15: Rotational Speed N | C15: 500 | D15: rpm
B16: Equivalent Dynamic Load P | C16: =C13*C11+C14*C12 -> 35600 | D16: N
B17: Exponent p | C17: =IF(C6="Spherical Roller Bearing",3,1/3) -> 0.33333333
B18: Lh Life required | C18: 10000 | D18: hours
B19: L10 Life | C19: =(60*C18*C15)/1000000 -> 300 | D19: Hours
B20: Dynamic Load Capacity C | C20: =IF(C17=3,C16*((C19)^(1/C17)),C16*((C19)^C17)) -> 238318.13 | D20: N
B23: Dimensions of Bearing
B25: Outer Diameter D | C25: =Catlogue!N14 -> 110 | D25: mm | H25: References
B26: Inner Diameter d | C26: =Catlogue!N13 -> 70 | D26: mm | H26: IS3823 | I26: Formulas
B27: Bore B | C27: =Catlogue!N15 -> 20 | D27: mm | H27: IS6455 | I27: Catlogue Dimensions
B28: Number of balls Z | C28: =IF(ROUND((((C25+C26)/2)*3.14)/(C8+5),0)<10,ROUND((((C25+C26)/2)*3.14)/(C8+5),0)+10,ROUND((((C25+C26)/2)*3.14)/(C8+5),0)) -> 28

Sheet X and Y factor Table
A1: Fa/C0 | B1: X (<=e) | C1: Y (<=e) | D1: X (>e) | E1: Y (>e) | F1: e
A2: 0.025 | B2: 1 | C2: 0.1 | D2: 0.56 | E2: 2 | F2: 0.22
A3: 0.04 | B3: 1 | C3: 0.1 | D3: 0.56 | E3: 1.8 | F3: 0.24
A4: 0.07 | B4: 1 | C4: 0.1 | D4: 0.56 | E4: 1.6 | F4: 0.27
A5: 0.13 | B5: 1 | C5: 0.1 | D5: 0.56 | E5: 1.4 | F5: 0.31
A6: 0.25 | B6: 1 | C6: 0.1 | D6: 0.56 | E6: 1.2 | F6: 0.37
A7: 0.5 | B7: 1 | C7: 0.1 | D7: 0.56 | E7: 1 | F7: 0.44
A10: Fa | B10: 10000 | C10: N | E10: Fa/C0 | F10: =B10/B12 -> 32.520325
A11: Fr | B11: ='Bearing Life Calculator'!C11 -> 10000 | C11: N | E11: Fa/Fr | F11: =B10/B11 -> 1
A12: C0 | B12: ='Bearing Life Calculator'!C10 -> 307.5 | C12: N | E12: e | F12: =IF(F10<=A2, F2, IF(F10>=A7, F7, _xlfn.FORECAST.LINEAR(F10, OFFSET(F1, MATCH(F10,A2:A7,1), 0, 2), OFFSET(A1, MATCH(F10,A2:A7,1), 0, 2)))) -> 0.44
E13: p | F13: =1/3 -> 0.33333333
A15: X | B15: =IF(F11<=F12,B2,D2) -> 0.56
A16: Y | B16: =IF(F11 <= F12, 0.1, IF(F10 <= A2, E2, IF(F10 >= A7, E7, _xlfn.FORECAST.LINEAR(F10, OFFSET(E1, MATCH(F10, A2:A7, 1), 0, 2), OFFSET(A1, MATCH(F10, A2:A7, 1), 0, 2))))) -> 1

Sheet Catlogue
A1: ID | B1: Bearing No | C1: Bore d (mm) | D1: Outside Diameter D (mm) | E1: Width B (mm) | F1: Deep Groove C10 (N) | G1: Spherical Roller Bearing C10 (N) | H1: Radial (N) | I1: Axial (N) | J1: Weight (kg)
A2: 1 | B2: 607 | C2: 7 | D2: 19 | E2: 6 | F2: 14100 | G2: 12100 | H2: 2340 | I2: 950 | J2: 0.01
A3: 2 | B3: 608 | C3: 8 | D3: 22 | E3: 7 | F3: 25900 | G3: 27100 | H3: 3450 | I3: 1370 | J3: 0.01
A4: 3 | B4: 609 | C4: 9 | D4: 24 | E4: 7 | F4: 31200 | G4: 23300 | H4: 3900 | I4: 1660 | J4: 0.01
A5: 4 | B5: 6000 | C5: 10 | D5: 26 | E5: 8 | F5: 39100 | G5: 38500 | H5: 4750 | I5: 1950 | J5: 0.02 | M5: Type of Bearing | N5: ='Bearing Life Calculator'!C6 -> Deep Groove Ball Bearing
A6: 5 | C6: 10 | D6: 30 | E6: 9 | F6: 50700 | G6: 49400 | H6: 5075 | I6: 2155 | J6: 0.02 | M6: Radial | N6: ='Bearing Life Calculator'!C11 -> 10000
A7: 6 | B7: 6001 | C7: 12 | D7: 28 | E7: 8 | F7: 59800 | G7: 59800 | H7: 5400 | I7: 2360 | J7: 0.02 | M7: Axial | N7: ='Bearing Life Calculator'!C12 -> 30000
A8: 7 | C8: 12 | D8: 32 | E8: 10 | F8: 68900 | G8: 70200 | H8: 5625 | I8: 2605 | J8: 0.025 | M8: Load Rating | N8: ='Bearing Life Calculator'!C20 -> 238318.13
A9: 8 | B9: 6002 | C9: 15 | D9: 32 | E9: 9 | F9: 73450 | G9: 75400 | H9: 5850 | I9: 2850 | J9: 0.03 | M9: Selected ID | N9: {=INDEX(A2:A42,MATCH(1,(H2:H42>=N6)*(I2:I42>=N7)*(IF(N5="Deep Groove Ball Bearing",F2:F42,G2:G42)>=N8),0))} -> 32
A10: 9 | C10: 15 | D10: 35 | E10: 11 | F10: 78000 | G10: 80600 | H10: 6110 | I10: 3050 | J10: 0.035
A11: 10 | B11: 6003 | C11: 17 | D11: 35 | E11: 10 | F11: 86800 | G11: 90050 | H11: 6370 | I11: 3250 | J11: 0.04
A12: 11 | C12: 17 | D12: 40 | E12: 12 | F12: 95600 | G12: 99500 | H12: 8160 | I12: 4125 | J12: 0.055
A13: 12 | B13: 6004 | C13: 20 | D13: 42 | E13: 12 | F13: 111300 | G13: 116250 | H13: 9950 | I13: 5000 | J13: 0.07 | M13: d | N13: =_xlfn.XLOOKUP(N9,A2:A42,C2:C42) -> 70
A14: 13 | C14: 20 | D14: 47 | E14: 14 | F14: 127000 | G14: 133000 | H14: 10925 | I14: 5775 | J14: 0.075 | M14: D | N14: =_xlfn.XLOOKUP(N9,A2:A42,D2:D42) -> 110
A15: 14 | B15: 6005 | C15: 25 | D15: 47 | E15: 12 | F15: 133500 | G15: 140500 | H15: 11900 | I15: 6550 | J15: 0.08 | M15: B | N15: =_xlfn.XLOOKUP(N9,A2:A42,E2:E42) -> 20
A16: 15 | C16: 25 | D16: 52 | E16: 15 | F16: 140000 | G16: 148000 | H16: 12850 | I16: 7425 | J16: 0.1
A17: 16 | B17: 6006 | C17: 30 | D17: 55 | E17: 13 | F17: 167500 | G17: 175500 | H17: 13800 | I17: 8300 | J17: 0.12
A18: 17 | C18: 30 | D18: 62 | E18: 16 | F18: 195000 | G18: 203000 | H18: 15300 | I18: 9250 | J18: 0.14
A19: 18 | B19: 6007 | C19: 35 | D19: 62 | E19: 14 | F19: 225000 | G19: 236500 | H19: 16800 | I19: 10200 | J19: 0.16
A20: 19 | C20: 35 | D20: 72 | E20: 17 | F20: 255000 | G20: 270000 | H20: 17300 | I20: 10900 | J20: 0.175
A21: 20 | B21: 6008 | C21: 40 | D21: 68 | E21: 15 | F21: 281000 | G21: 294500 | H21: 17800 | I21: 11600 | J21: 0.19
A22: 21 | C22: 40 | D22: 80 | E22: 18 | F22: 307000 | G22: 319000 | H22: 19950 | I22: 13100 | J22: 0.22
A23: 22 | B23: 6009 | C23: 45 | D23: 75 | E23: 16 | F23: 319500 | G23: 338500 | H23: 22100 | I23: 14600 | J23: 0.25
A24: 23 | C24: 45 | D24: 85 | E24: 19 | F24: 332000 | G24: 358000 | H24: 22500 | I24: 15300 | J24: 0.255
A25: 24 | B25: 6010 | C25: 50 | D25: 80 | E25: 16 | F25: 341500 | G25: 367500 | H25: 22900 | I25: 16000 | J25: 0.26
A26: 25 | C26: 50 | D26: 90 | E26: 20 | F26: 351000 | G26: 377000 | H26: 26250 | I26: 18600 | J26: 0.325
A27: 26 | B27: 6011 | C27: 55 | D27: 90 | E27: 18 | F27: 393500 | G27: 419500 | H27: 29600 | I27: 21200 | J27: 0.39
A28: 27 | C28: 55 | D28: 100 | E28: 21 | F28: 436000 | G28: 462000 | H28: 30150 | I28: 22200 | J28: 0.405
A29: 28 | B29: 6012 | C29: 60 | D29: 95 | E29: 18 | F29: 455500 | G29: 510500 | H29: 30700 | I29: 23200 | J29: 0.42
A30: 29 | C30: 60 | D30: 110 | E30: 22 | F30: 475000 | G30: 559000 | H30: 31300 | I30: 24100 | J30: 0.43
A31: 30 | B31: 6013 | C31: 65 | D31: 100 | E31: 18 | F31: 517000 | G31: 598000 | H31: 31900 | I31: 25000 | J31: 0.44
A32: 31 | C32: 65 | D32: 120 | E32: 23 | F32: 559000 | G32: 637000 | H32: 35800 | I32: 28000 | J32: 0.52
A33: 32 | B33: 6014 | C33: 70 | D33: 110 | E33: 20 | F33: 588500 | G33: 663000 | H33: 39700 | I33: 31000 | J33: 0.6
A34: 33 | C34: 70 | D34: 125 | E34: 24 | F34: 618000 | G34: 689000 | H34: 40650 | I34: 32250 | J34: 0.62
A35: 34 | B35: 6015 | C35: 75 | D35: 115 | E35: 20 | F35: 640500 | G35: 702000 | H35: 41600 | I35: 33500 | J35: 0.64
A36: 35 | C36: 75 | D36: 130 | E36: 25 | F36: 663000 | G36: 715000 | H36: 45500 | I36: 36750 | J36: 0.745
A37: 36 | B37: 6016 | C37: 80 | D37: 125 | E37: 22 | F37: 682500 | G37: 760500 | H37: 49400 | I37: 40000 | J37: 0.85
A38: 37 | C38: 80 | D38: 140 | E38: 26 | F38: 702000 | G38: 806000 | H38: 50700 | I38: 41500 | J38: 0.87
A39: 38 | B39: 6017 | C39: 85 | D39: 130 | E39: 22 | F39: 767000 | G39: 855000 | H39: 52000 | I39: 43000 | J39: 0.89
A40: 39 | C40: 85 | D40: 150 | E40: 28 | F40: 832000 | G40: 904000 | H40: 53000 | I40: 47000 | J40: 0.95
...
