Workbook

Sheet INPUT SHEET
B2: INPUT DATA FOR BELT CONVEYORS
A4: SL.NO. | B4: CONVEYOR | C4: RATED CAPACITY (TPH) | D4: LIFT (M) | E4: C/C DISTANCE (M) | F4: BELT SPEED (M/SEC) | G4: TOTAL SKIRT LENGTH (M) | H4: TYPE OF TAKE-UP | I4: POWER
A5: 1 | B5: BC-603 | C5: 1500 | D5: 7 | E5: 60 | F5: 2.5 | G5: 3 | H5: gravity | I5: =POWER!B144 -> 110
I6: =POWER!B140 -> 95.453871
C10: Corrections done on 05.03.2016 for Rska & Rsk (Multifying factor 2 has been removed)
C12: This is final & correct

Sheet DATA BANK
A2: 1. TABLE FOR WEIGHT OF 3-ROLL IDLER SETS WITHOUT FRAMES (AS PER IPSS)
A4: Belt width in mm | B4: Dia. Of idler | C4: Wt. In N per roll for 3-roll set | D4: Flat idler weight in N
A6: 650 | B6: 101.6 | C6: 39 | D6: 74
A7: 650 | B7: 114.3 | C7: 46 | D7: 94 | G7: Diameter of idler | H7: {=_xlfn._xlws.FILTER($B$6:$B$26,$A$6:$A$26=POWER!B12)} -> 114.3
A8: 650 | B8: 127 | C8: 49 | D8: 101 | H8: 127
H9: 139.7
A10: 800 | B10: 114.3 | C10: 76 | D10: 151 | H10: 152.4
A11: 800 | B11: 127 | C11: 78 | D11: 162
A12: 800 | B12: 139.7 | C12: 79 | D12: 176
A13: 800 | B13: 152.4 | C13: 111 | D13: 194
A15: 1000 | B15: 114.3 | C15: 86 | D15: 181
A16: 1000 | B16: 127 | C16: 102 | D16: 192
A17: 1000 | B17: 139.7 | C17: 114 | D17: 207
A18: 1000 | B18: 152.4 | C18: 127 | D18: 222
A20: 1200 | B20: 114.3 | C20: 96 | D20: 213
A21: 1200 | B21: 127 | C21: 123 | D21: 229
A22: 1200 | B22: 139.7 | C22: 132 | D22: 247
A23: 1200 | B23: 152.4 | C23: 141 | D23: 266
A25: 1400 | B25: 139.7 | C25: 142 | D25: 280
A26: 1400 | B26: 152.4 | C26: 153 | D26: 315
A29: 2. BELT DETAILS | D29: (HEAVY DUTY)
A32: Belt type | B32: Nominal carcass thickness (mm) | C32: MRBT (kN/m) | D32: Minimum Pulley diameter for satisfactoiry flexing (mm)
D33: Drive | E33: Terminal tripper and high tension snub pulleys | F33: Low tension bend and snub pulleys
A35: 315/3 | B35: 4.2 | C35: 31 | D35: 450 | E35: 400 | F35: 300
A36: 630/3 | B36: 4 | C36: 63 | D36: 500 | E36: 450 | F36: 350
A37: 630/4 | B37: 6.7 | C37: 70 | D37: 650 | E37: 500 | F37: 400
A38: 800/4 | B38: 7.1 | C38: 90 | D38: 800 | E38: 650 | F38: 450
A39: 1250/4 | B39: 6.7 | C39: 140 | D39: 630 | E39: 500 | F39: 400
A41: 3. PULLEY SELECTION TABLE
A43: Carcass thickness (mm) | D43: RMBTC >60% UPTO 100%) | H43: RMBTC >30% UPTO 60%) | L43: RMBTC UPTO 30%)
A44: From | B44: To | D44: Drive | E44: Tail/Take-up/Bend | F44: Sunb | H44: Drive | I44: Tail/Take-up/Bend | J44: Sunb | L44: Drive | M44: Tail/Take-up/Bend | N44: Sunb
A46: - | B46: 1.1 | D46: 100 | E46: - | F46: - | H46: - | I46: - | J46: - | L46: - | M46: - | N46: -
A47: 1.2 | B47: 1.3 | D47: 125 | E47: 100 | F47: - | H47: 100 | I47: - | J47: - | L47: - | M47: - | N47: -
A48: 1.4 | B48: 1.7 | D48: 160 | E48: 125 | F48: 100 | H48: 125 | I48: 100 | J48: - | L48: 100 | M48: 100 | N48: -
A49: 1.8 | B49: 2.2 | D49: 200 | E49: 160 | F49: 125 | H49: 160 | I49: 125 | J49: 100 | L49: 125 | M49: 125 | N49: 100
A50: 2.3 | B50: 2.7 | D50: 250 | E50: 200 | F50: 160 | H50: 200 | I50: 160 | J50: 125 | L50: 160 | M50: 160 | N50: 125
A51: 2.8 | B51: 3.5 | D51: 315 | E51: 250 | F51: 200 | H51: 250 | I51: 200 | J51: 160 | L51: 200 | M51: 200 | N51: 160
A52: 3.6 | B52: 4.4 | D52: 400 | E52: 315 | F52: 250 | H52: 315 | I52: 250 | J52: 200 | L52: 250 | M52: 250 | N52: 200
A53: 4.5 | B53: 5.5 | D53: 500 | E53: 400 | F53: 315 | H53: 400 | I53: 315 | J53: 250 | L53: 315 | M53: 315 | N53: 250
A54: 5.6 | B54: 7 | D54: 630 | E54: 500 | F54: 400 | H54: 500 | I54: 400 | J54: 315 | L54: 400 | M54: 400 | N54: 315
...

Sheet IDLER DETAILS
A4: Sl.No. | B4: CONVEYOR Description | C4: C/C (m) | D4: Carrying | E4: SAC | F4: Impact | G4: Return | H4: SAR | I4: Transition idlers (11 deg) | J4: Transition idlers (20 deg) | K4: Pull cord switches | L4: Belt sway switches | M4: Zero speed switch
A5: 1 | B5: K-11 | C5: ='INPUT SHEET'!E5 -> 60 | D5: =ROUNDUP(+(C5-0.5*F5-E5-I5-J5)/1,0) -> 45 | E5: =ROUNDUP((+C5-5-5)/15,0)+1 -> 5 | F5: 12 | G5: =ROUNDUP(+C5/3,0)-H5 -> 15 | H5: =ROUNDUP((+C5-5-5)/15,0)+1 -> 5 | I5: 2 | J5: 2 | K5: =ROUNDUP((+C5-5-5)/30,0)+1 -> 3 | L5: =ROUNDUP((+C5-5-5)/30,0)+1 -> 3 | M5: 1

Sheet POWER
A1: POWER CALCULATION FOR BELT CONVEYOR | B1: ='INPUT SHEET'!B5 -> BC-603
A2: (BASED ON IS 11592:2000)
A4: Conveyor Capacity | C4: Achievable rated capacity (tph) =
A5: Margin | B5: 1.2 | C5: ='DATA BANK'!H132 -> 792.52992
A6: Designed Qd (tph)= | B6: =B5*'INPUT SHEET'!C5 -> 1800
A7: Material: | B7: 1 | C7: CARRYING IDLER SELECTION (AS PER IPSS)
A8: Bulk density=r (t/m^3)= | B8: 0.8
A9: Pulley c/c ( L) (m): | B9: ='INPUT SHEET'!E5 -> 60 | C9: Wb= weight of belt in N/m= | D9: =+B59*B35 -> 152.73826
A10: Lift (H) (m) : | B10: ='INPUT SHEET'!D5 -> 7 | C10: Wm=weight of material in N/m= | D10: =+B61*B35 -> 1961.2
A11: Belt speed (v) (m/sec) : | B11: ='INPUT SHEET'!F5 -> 2.5 | C11: Si= idler spacing in m= | D11: 1
A12: Belt width (mm) (B) : | B12: 800 | C12: ACTUAL IDLER LOAD = IL (N) = | D12: =+(D9+D10)*D11 -> 2113.9383
A13: Ambient temp. :(t) | B13: 50 deg.C | C13: K1= | D13: 1
A14: Length of skirt : Lsk (m)= | B14: ='INPUT SHEET'!G5 -> 3 | C14: K2= | D14: 1.15
A15: Type of belt : | C15: K3= | D15: 1.2
A16: Material | B16: N/N | C16: K4= | D16: 0.9
A17: Grade | B17: HD | C17: ADJUSTED LOAD = AL (N)= | D17: =+D12*D13*D14*D15*D16 -> 2625.5113
A18: Top cover thickness (mm) | B18: 8
A19: Bottom cover thickness (mm) | B19: 3 | C19: SELECTED IDLER= | D19: 114.3
A20: Type | B20: 2 | C20: Class of Idlers= | D20: Class-III | I20: Correct Belt type | K20: 630/4
C21: Duty of idlers= | D21: Medium duty
A22: DESIGN CALCULATION | C22: SHAFT DIA. AT BEARING (mm)= | D22: 25
A24: A. MOTOR POWER & TENSION
A26: Peripheral force Te (effective tension) on the driving pulley of belt conveyor is | C26: RETURNG IDLER SELECTION (AS PER IPSS)
A27: is obtained by adding up all the resistances:
C28: Wb= weight of belt in N/m= | D28: =+D9 -> 152.73826
A29: Te=R+Rs+Rsp1+Rsp2+Rsl | C29: Si= idler spacing in m= | D29: 1
A30: 1. R= Main Resistances | C30: ACTUAL IDLER LOAD = IL (N) = | D30: =+(D28)*D29 -> 152.73826
A31: R=f*L*g*(mc+mr+(2*mB+mG)*cos d) | C31: K1= | D31: 1.1
A32: R=Main resistance in Newtons (N) | C32: K2= | D32: 1.15
A33: f= Artificial co-efficient of friction = | B33: 0.03 | C33: K3= | D33: 1.2
A34: L= Conveyor Length (m)= | B34: =+B9 -> 60 | C34: K4= | D34: 1
A35: g (m/sec^2)= | B35: 9.806 | C35: ADJUSTED LOAD = AL (N) = | D35: =+D30*D31*D32*D33*D34 -> 231.85667
A36: d (degree) = Slope angle of conveyor = | B36: 7.73
A37: cos d= | B37: =COS((B36*3.1417)/180) -> 0.99091229 | C37: SELECTED IDLER= | D37: 114.3
A38: mc= mass of revolving idler part along the carrying side of idler per set (kg/m)= | C38: Class of Idlers= | D38: Class-III
A39: Diameter of idler (mm)= | B39: 139.7 | C39: Duty of idlers= | D39: Medium duty
A40: No. of idler set= | B40: ='IDLER DETAILS'!D5+'IDLER DETAILS'!E5 -> 50 | C40: SHAFT DIA. AT BEARING (MM)= | D40: 25
A41: Wt. Of each idler= | B41: 141
A42: Wt. Of each idler set (3 idler set)= | B42: =3*B41 -> 423
A43: Diameter of impact idler= | B43: =B39 -> 139.7
...

Sheet CHUTE SIZING
B2: Conveyor Capacity
B3: Rated Qr (tph)= | C3: ='INPUT SHEET'!C5 -> 1500
B4: Designed Qd (tph)= | C4: =POWER!B6 -> 1800
B5: Bulk density=r= (t/m^3) | C5: =POWER!B8 -> 0.8
B6: Belt Speed=v (m/sec) | C6: ='INPUT SHEET'!F5 -> 2.5
B7: Cross Sectional area of chute=A (m2)=Qd/v * 3600 *r | C7: =C4/(C6*3600*C5) -> 0.25
B8: Chute dimension (one side)= 1000 * √A mm | C8: =100+SQRT(C7)*1000 -> 600
B9: Chute dimension (other side) | C9: =C8 -> 600

Sheet Sheet1
B1: Compatibility Report for Conveyor Calculation Official.xls
B2: Run on 08-06-2026 12:10
B4: If the workbook is saved in an earlier file format or opened in an earlier version of Microsoft Excel, the listed features will not be available.
B6: Significant loss of functionality | E6: No. of occurrences | F6: Version
B8: One or more cells in this workbook contain a formula that has spilled or may spill in the future. These formulas will be converted into legacy array formulas and will not spill or change dimension in older versions of Excel. | E8: 1
E9: DATA BANK'!H7 | F9: Excel 97-2003
F10: Excel 2007
F11: Excel 2010
F12: Excel 2013
F13: Excel 2016
F14: Excel 2019
B16: One or more functions or operators in this workbook are not available in earlier versions of Excel. When recalculated in earlier versions, these formulae will return a #NAME? error instead of calculated results. | E16: 3
E17: DATA BANK'!H7 | F17: Excel 97-2003
F18: Excel 2007
F19: Excel 2010
F20: Excel 2013
F21: Excel 2016
F22: Excel 2019
E23: POWER'!B56 | F23: Excel 97-2003
E24: POWER'!B39 | F24: Excel 2007
F25: Excel 2010
F26: Excel 2013
F27: Excel 2016
F28: Excel 2019
