Workbook

Sheet Belt Conveyor Motor Power
B2: IS 11592: 2000 Belt Conveyor Motor Power Calculator
B4: Parameter | C4: Symbol | D4: Value | E4: Unit
B5: Capacity | C5: C | D5: 200 | E5: t/h
B6: Material | D6: Limestone
B7: Bulk Density | C7: \rho | D7: =_xlfn.XLOOKUP(D6,'Density - IS8730'!A2:A455,'Density - IS8730'!B2:B455) -> 1.4 | E7: t/m³
B8: Lump Size | D8: Granular
B9: Abrasiveness | D9: Abrasiveness
B10: Speed Factor | D10: =(_xlfn.XLOOKUP(D8,F118:F121,G118:G121)+(_xlfn.XLOOKUP(D9,J117:J120,K117:K120))) -> 4
B11: Belt Speed | C11: V | D11: =INDEX(G132:S139,MATCH(D10,F132:F139,0),MATCH(D13,G130:S130,0)) -> 2.75 | E11: m/s
B12: Initial Velocity | C12: V_0 | D12: 0 | E12: m/s
B13: Belt Width | C13: B | D13: 800 | E13: mm
B14: Trough Angle | D14: 25 | E14: degree
B15: Surcharge Angle | D15: 30 | E15: degree
B16: Belt Width | C16: B | D16: =D13/1000 -> 0.8 | E16: m
B17: Cross-sectional area of load on belt | C17: A | D17: {=INDEX('Table 7 - Max Area'!$C$3:$H$54, MATCH(1,('Table 7 - Max Area'!$A$3:$A$54=$D$13)*('Table 7 - Max Area'!$B$3:$B$54=$D$15),0), MATCH($D$14,'Table 7 - Max Area'!$C$2:$H$2,0))} -> 0.0722 | E17: m2
B18: Conveyor Length | C18: L | D18: 109 | E18: m
B19: Lift / Elevation | C19: H | D19: 24 | E19: m
B20: Slope Angle | D20: =DEGREES(ATAN(D19/D18)) -> 12.417446 | E20: degrees
B21: Slope Factor | C21: K | D21: =_xlfn.XLOOKUP(EVEN(ROUNDUP(D20,0)),B118:B127,C118:C127) -> 0.91
B22: Working time | C22: t | D22: 10 | E22: hours
B23: Service Factor | C23: SF | D23: {=_xlfn.IFS(D22<8, 1.2, AND(D22>=8, D22<=12), 1.6, D22>12, 2)} -> 1.6
B24: Artif. Friction Coeff | C24: f | D24: 0.02 | E24: -
B25: Mass of carrying idlers | C25: m_c | D25: 20 | E25: kg/m
B26: Mass of return idlers | C26: m_r | D26: 10 | E26: kg/m
B27: Mass of belt | C27: m_B | D27: 15 | E27: kg/m
B28: Friction (Mat-Belt) | C28: \mu_1 | D28: 0.6 | E28: -
B29: Friction (Mat-Skirt) | C29: \mu_2 | D29: 0.6 | E29: -
B30: Skirt width | C30: b_1 | D30: 0.7 | E30: m
B31: Skirt length | C31: l_sk | D31: 2 | E31: m
B32: Belt Thickness | C32: t | D32: 0.015 | E32: m
B33: Pulley Diameter | C33: D | D33: 0.6 | E33: m
B34: Shaft Dia at bearing | C34: d | D34: 0.1 | E34: m
B35: Vector sum tensions | C35: R_v | D35: 20000 | E35: N
... B40: Idler Tilt Angle | C40: i | D40: 3 | E40: degrees
B41: Area of belt cleaner | C41: A_1 | D41: =((D51*(D13/1000)*(D53/1000)*D55*D43)+(D52*(D13/1000)*(D54/1000)*D56*D43))/1000000 -> 0.0014144 | E41: m²
B42: Cleaner Pressure | C42: p | D42: 30000 | E42: N/m²
B43: Friction (Belt-Cleaner) | C43: \mu_3 | D43: 0.65 | E43: -
B44: Scraping Factor | C44: K_s | D44: 1500 | E44: N/m
B45: Drive Efficiency | C45: \eta_1 | D45: 0.94 | E45: -
B46: Gravity | C46: g | D46: 9.81 | E46: m/s²
...

Sheet Density - IS8730
A1: Material | B1: Average Bulk Density, t/m³
A2: Adipic acid | B2: 0.72
A3: Alfalfa seed | B3: 0.2
A4: Alfalfa meal | B4: 0.272
A5: Almonds, broken or whole | B5: 0.464
A6: Alum, fine | B6: 0.76
A7: Alum, lumpy | B7: 0.88
A8: Alum, pulverised | B8: 0.76
A9: Alumina | B9: 0.92
A10: Aluminate jell | B10: 0.72
A11: Aluminium chips | B11: 0.175
A12: Aluminium hydrate | B12: 0.288
A13: Aluminium oxide | B13: 1.5
... A455: Zinc oxide, light | B455: 0.2

Sheet Table 7 - Max Area
A1: Belt Width (mm) | B1: Surcharge Angle | C1: Trough Angle
C2: 20 | D2: 25 | E2: 30 | F2: 35 | G2: 40 | H2: 45 | J2: Belt Width | K2: ='Belt Conveyor Motor Power'!D13 -> 800
A3: 500 | B3: 0 | C3: 0.0098 | D3: 0.012 | E3: 0.0139 | F3: 0.0157 | G3: 0.0173 | H3: 0.0186 | J3: Trough Angle | K3: ='Belt Conveyor Motor Power'!D14 -> 25
A4: 500 | B4: 10 | C4: 0.0142 | D4: 0.0162 | E4: 0.018 | F4: 0.0196 | G4: 0.021 | H4: 0.022 | J4: Surcharge Angle | K4: ='Belt Conveyor Motor Power'!D15 -> 30
A5: 500 | B5: 20 | C5: 0.0187 | D5: 0.0206 | E5: 0.0222 | F5: 0.0236 | G5: 0.0247 | H5: 0.0256
A6: 500 | B6: 30 | C6: 0.0234 | D6: 0.0252 | E6: 0.0266 | F6: 0.0278 | G6: 0.0287 | H6: 0.0293
A7: 650 | B7: 0 | C7: 0.0184 | D7: 0.0224 | E7: 0.026 | F7: 0.0294 | G7: 0.0322 | H7: 0.0347 | J7: Area | K7: {=INDEX($C$3:$H$54,MATCH(1,($A$2:$A$54=K2)*($B$2:$B$54=K4),0),MATCH(K3,$C$2:$H$2,0))} -> 0.0582 | L7: m2
A8: 650 | B8: 10 | C8: 0.0262 | D8: 0.0299 | E8: 0.0332 | F8: 0.0362 | G8: 0.0386 | H8: 0.0407
A9: 650 | B9: 20 | C9: 0.0342 | D9: 0.0377 | E9: 0.0406 | F9: 0.0433 | G9: 0.0453 | H9: 0.0469
A10: 650 | B10: 30 | C10: 0.0427 | D10: 0.0459 | E10: 0.0484 | F10: 0.0507 | G10: 0.0523 | H10: 0.0534
A11: 800 | B11: 0 | C11: 0.0279 | D11: 0.0344 | E11: 0.0402 | F11: 0.0454 | G11: 0.05 | H11: 0.054
A12: 800 | B12: 10 | C12: 0.0405 | D12: 0.0466 | E12: 0.0518 | F12: 0.0564 | G12: 0.0603 | H12: 0.0636
A13: 800 | B13: 20 | C13: 0.0535 | D13: 0.0591 | E13: 0.0638 | F13: 0.0678 | G13: 0.0707 | H13: 0.0736
A14: 800 | B14: 30 | C14: 0.0671 | D14: 0.0722 | E14: 0.0763 | F14: 0.0798 | G14: 0.0822 | H14: 0.084
A15: 1000 | B15: 0 | C15: 0.0478 | D15: 0.0582 | E15: 0.0677 | F15: 0.0763 | G15: 0.0838 | H15: 0.0898
A16: 1000 | B16: 10 | C16: 0.0674 | D16: 0.0771 | E16: 0.0857 | F16: 0.0933 | G16: 0.0998 | H16: 0.105
A17: 1000 | B17: 20 | C17: 0.0876 | D17: 0.0966 | E17: 0.104 | F17: 0.111 | G17: 0.116 | H17: 0.12
A18: 1000 | B18: 30 | C18: 0.109 | D18: 0.117 | E18: 0.134 | F18: 0.129 | G18: 0.134 | H18: 0.136
A19: 1200 | B19: 0 | C19: 0.07 | D19: 0.085 | E19: 0.099 | F19: 0.112 | G19: 0.123 | H19: 0.132
... A54: 2800 | B54: 30 | C54: 0.928 | D54: 0.998 | E54: 1.063 | F54: 1.104 | G54: 1.137 | H54: 1.158
