Workbook

Sheet VSMA Screen Design
C3: VIBRATING SCREEN DESIGN CALCULATOR
C5: Parameter | D5: Input | E5: Unit
C6: Feed Capacity Q | D6: 190 | E6: TPH
C7: Material | D7: Sand, bank, dry
C8: Bulk Density | D8: =_xlfn.XLOOKUP(D7,'Density - IS8730'!A2:A455,'Density - IS8730'!B2:B455) -> 1.6 | E8: t/m³
C9: Feed Size | D9: 13 | E9: mm
C10: Aperture Size | D10: 15 | E10: mm
C11: Specific feed rate | D11: =_xlfn.XLOOKUP(D9,'Reference Tables'!G4:G55,'Reference Tables'!H4:H55, ,1) -> 15.7 | E11: m2/hr
C12: Material Factor | D12: =_xlfn.XLOOKUP(D8,'Reference Tables'!B19:B27,'Reference Tables'!C19:C27, ,1) -> 1
C13: Oversize Factor | D13: =_xlfn.XLOOKUP(D35,'Reference Tables'!K5:K23,'Reference Tables'!L5:L23, ,1) -> 0.95
C14: Efficiency Factor | D14: =_xlfn.XLOOKUP(D23,'Reference Tables'!K27:K42,'Reference Tables'!L27:L42, ,1) -> 1.1
C15: Half size cut factor | D15: 0.96
C16: Amplitude Factor | D16: =IF((D10-D9)>16,3.5,4.5) -> 4.5
C17: Inclination | D17: 7 | E17: degree
C18: Moisture Condition | D18: Slightly damp
C19: Particle Shape | D19: Rounded
C20: Moisture Factor | D20: =_xlfn.XLOOKUP(D18,'Reference Tables'!B4:B7,'Reference Tables'!C4:C7) -> 0.9
C21: Shape Factor K | D21: =_xlfn.XLOOKUP(D19,'Reference Tables'!B12:B15,'Reference Tables'!C12:C15) -> 1.1
C22: Inclination Factor | D22: =_xlfn.XLOOKUP(D17,'Reference Tables'!B41:B61,'Reference Tables'!C41:C61,,1) -> 1.25
C23: Efficiency Requirement | D23: 90 | E23: %
C24: Open Area Factor O | D24: 0.95
C25: Deck Factor | D25: {=_xlfn.IFS(D28=1,1,D28=2,0.9,D28=3,0.8,D28=4,0.7,D28=5,0.6)} -> 0.8
C26: Amplitude | D26: 6 | E26: mm
C27: Screen Type | D27: Linear
C28: No. of Decks | D28: 3
C29: Motion Speed | D29: =_xlfn.XLOOKUP(D27,'Reference Tables'!K46:K48,'Reference Tables'!L46:L48) -> 0.2 | E29: m/s
C30: Stroke | D30: 8 | E30: mm
C31: Motor Speed | D31: 950 | E31: rpm
C32: Weight of Oscillating part | D32: 202 | E32: kg
C33: Feed Size a | D33: 90 | E33: %
C34: Undersize Product b | D34: =(D9/D10)*100 -> 86.666667 | E34: %
C35: Oversize Product c | D35: =_xlfn.XLOOKUP(D10-D9,'Reference Tables'!B32:B36,'Reference Tables'!C32:C36, , 1) -> 13.7 | E35: %
C38: Calculation | D38: Calculations | E38: Unit
C39: Basic Capacity Factor C | D39: =IF(D10<=5,8,IF(D10<=10,15,IF(D10<=25,30,50))) -> 30 | E39: TPH/m²
C40: Efficiency Factor E | D40: =D23/100 -> 0.9 | E40: -
C41: Required Screen Area A | D41: =D6/(D11*D12*D13*D14*D15*D20*D21*D24*D25*D22) -> 12.826484 | E41: m²
C42: Width | D42: =IF(D6<50,1.2,IF(D6<150,1.8,IF(D6<300,2.4,3))) -> 2.4 | E42: m
C43: Length | D43: =D41/D42 -> 5.3443684 | E43: m
C44: Speed | D44: =SQRT((D16*90000)/D26) -> 259.80762 | E44: rpm
C45: Length / Width Ratio | D45: =D43/D42 -> 2.2268201 | E45: -
...

Sheet Density - IS8730
A1: Material | B1: Average Bulk Density, t/m³
A2: Adipic acid | B2: 0.72
A3: Alfalfa seed | B3: 0.2
A4: Alfalfa meal | B4: 0.272
A5: Almonds, broken or whole | B5: 0.464
A6: Alum, fine | B6: 0.76
A7: Alum, lumpy | B7: 0.88
A8: Alum, pulverised | B8: 0.76
A9: Alumina | B9: 0.92
A10: Aluminate jell | B10: 0.72
A11: Aluminium chips | B11: 0.175
A12: Aluminium hydrate | B12: 0.288
A13: Aluminium oxide | B13: 1.5
... A455: Zinc oxide, light | B455: 0.2

Sheet Reference Tables
B2: Moisture Factor
B3: Material Condition | C3: Moisture Factor | G3: Feed Size (mm) | H3: q (m³/m²/hr) | K3: Over Size Factor Table
B4: Dry | C4: 1 | G4: 1 | H4: 1.3 | K4: % over size | L4: C1
B5: Slightly damp | C5: 0.9 | G5: 2 | H5: 3.3 | K5: 2 | L5: 0.85
B6: Wet | C6: 0.8 | G6: 3 | H6: 5.6 | K6: 4 | L6: 0.86
B7: Sticky wet | C7: 0.7 | G7: 4 | H7: 6.9 | K7: 6 | L7: 0.87
G8: 5 | H8: 9 | K8: 8 | L8: 0.88
G9: 6 | H9: 9.5 | K9: 10 | L9: 0.9
B10: Shape Factor | G10: 7 | H10: 10 | K10: 20 | L10: 0.95
B11: Particle Shape | C11: Shape Factor | G11: 8 | H11: 11 | K11: 25 | L11: 1
B12: Rounded | C12: 1.1 | G12: 9 | H12: 11.9 | K12: 30 | L12: 1.04
B13: Cubical | C13: 1 | G13: 10 | H13: 12.7 | K13: 40 | L13: 1.1
B14: Angular | C14: 0.9 | G14: 12 | H14: 14.3 | K14: 50 | L14: 1.2
B15: Flat/elongated | C15: 0.85 | G15: 14 | H15: 15.7 | K15: 60 | L15: 1.33
G16: 16 | H16: 17.1 | K16: 70 | L16: 1.55
G17: 18 | H17: 18.6 | K17: 80 | L17: 2.03
B18: Bulk Density | C18: M | G18: 20 | H18: 20 | K18: 85 | L18: 2.5
B19: 0.5 | C19: 1.3 | G19: 22 | H19: 21.2 | K19: 90 | L19: 3
B20: 0.8 | C20: 1.2 | G20: 24 | H20: 22.5 | K20: 92 | L20: 3.5
B21: 0.9 | C21: 1.5 | G21: 26 | H21: 24 | K21: 94 | L21: 3.9
B22: 1 | C22: 1.7 | G22: 28 | H22: 25 | K22: 96 | L22: 4.5
B23: 1.6 | C23: 1 | G23: 30 | H23: 25.2 | K23: 98 | L23: 6
B24: 1.6 | C24: 1.35 | G24: 32 | H24: 27.4
B25: 1.79 | C25: 1.1 | G25: 35 | H25: 28.5 | K25: Efficiency Factor
B26: 2.3 | C26: 1.5 | G26: 36 | H26: 29.5 | K26: Efficiency (%) | L26: C3
B27: 2.4 | C27: 1 | G27: 38 | H27: 30.8 | K27: 10 | L27: 6.5
G28: 40 | H28: 32 | K28: 20 | L28: 4.7
G29: 42 | H29: 33 | K29: 30 | L29: 3.7
G30: 44 | H30: 34 | K30: 40 | L30: 3
B31: Size | C31: % | G31: 46 | H31: 35 | K31: 50 | L31: 2.5
B32: 0 | C32: 22.1 | G32: 48 | H32: 36 | K32: 60 | L32: 2.1
B33: 5 | C33: 13.7 | G33: 50 | H33: 37 | K33: 70 | L33: 1.7
B34: 10 | C34: 27 | G34: 55 | H34: 40 | K34: 75 | L34: 1.55
B35: 25 | C35: 22.7 | G35: 60 | H35: 42 | K35: 80 | L35: 1.4
B36: 40 | C36: 14.5 | G36: 65 | H36: 44 | K36: 85 | L36: 1.25
G37: 70 | H37: 45 | K37: 90 | L37: 1.1
G38: 75 | H38: 45 | K38: 92 | L38: 1.05
G39: 80 | H39: 50 | K39: 94 | L39: 1
B40: Screen Inclination | C40: Factor C0 | G40: 85 | H40: 52.5 | K40: 96 | L40: 0.93
B41: 0 | C41: 1 | G41: 90 | H41: 55 | K41: 98 | L41: 0.93
...
